Workbook
Name SlicerCache_Table_2_Col_3: #N/A
Name SlicerCache_Table_1_Col_2: #N/A
Name SlicerCache_Table_3_Col_3: #N/A

Sheet Orders
A1: order_id | B1: order_date | C1: customer_id | D1: product_id | E1: quantity | F1: sales | G1: discount_pct | H1: discount_amount | I1: net_sales | J1: Customer_name
A2: 50001 | B2: 46027 | C2: 1007 | D2: P003 | E2: 1 | F2: 55 | G2: 5 | H2: 2.75 | I2: 52.25 | J2: {=_xlfn.XLOOKUP(C2,Customers!A:A,Customers!B:B)} -> Marco Bianchi
A3: 50002 | B3: 46029 | C3: 1020 | D3: P004 | E3: 4 | F3: 100 | G3: 0 | H3: 0 | I3: 100 | J3: {=_xlfn.XLOOKUP(C3,Customers!A:A,Customers!B:B)} -> Arjun Mehta
A4: 50003 | B4: 46031 | C4: 1015 | D4: P008 | E4: 1 | F4: 500 | G4: 0 | H4: 0 | I4: 500 | J4: {=_xlfn.XLOOKUP(C4,Customers!A:A,Customers!B:B)} -> Luca Ferrari
A5: 50004 | B5: 46033 | C5: 1011 | D5: P006 | E5: 1 | F5: 280 | G5: 10 | H5: 28 | I5: 252 | J5: {=_xlfn.XLOOKUP(C5,Customers!A:A,Customers!B:B)} -> Sofia Romano
A6: 50005 | B6: 46035 | C6: 1008 | D6: P003 | E6: 2 | F6: 110 | G6: 10 | H6: 11 | I6: 99 | J6: {=_xlfn.XLOOKUP(C6,Customers!A:A,Customers!B:B)} -> Priya Patel
A7: 50006 | B7: 46037 | C7: 1007 | D7: P003 | E7: 4 | F7: 220 | G7: 0 | H7: 0 | I7: 220 | J7: {=_xlfn.XLOOKUP(C7,Customers!A:A,Customers!B:B)} -> Marco Bianchi
A8: 50007 | B8: 46040 | C8: 1019 | D8: P001 | E8: 4 | F8: 3400 | G8: 5 | H8: 170 | I8: 3230 | J8: {=_xlfn.XLOOKUP(C8,Customers!A:A,Customers!B:B)} -> Giulia Conti
A9: 50008 | B9: 46042 | C9: 1011 | D9: P003 | E9: 2 | F9: 110 | H9: 0 | I9: 110 | J9: {=_xlfn.XLOOKUP(C9,Customers!A:A,Customers!B:B)} -> Sofia Romano
A10: 50009 | B10: 46044 | C10: 1011 | D10: P005 | E10: 3 | F10: 225 | G10: 5 | H10: 11.25 | I10: 213.75 | J10: {=_xlfn.XLOOKUP(C10,Customers!A:A,Customers!B:B)} -> Sofia Romano
A11: 50010 | B11: 46046 | C11: 1004 | D11: P007 | E11: 1 | F11: 95 | G11: 0 | H11: 0 | I11: 95 | J11: {=_xlfn.XLOOKUP(C11,Customers!A:A,Customers!B:B)} -> Simran Kaur
A12: 50011 | B12: 46048 | C12: 1008 | D12: P006 | E12: 5 | F12: 1400 | G12: 5 | H12: 70 | I12: 1330 | J12: {=_xlfn.XLOOKUP(C12,Customers!A:A,Customers!B:B)} -> Priya Patel
A13: 50012 | B13: 46051 | C13: 1003 | D13: P003 | E13: 1 | F13: 55 | G13: 15 | H13: 8.25 | I13: 46.75 | J13: {=_xlfn.XLOOKUP(C13,Customers!A:A,Customers!B:B)} -> John Miller
A14: 50013 | B14: 46053 | C14: 1002 | D14: P001 | E14: 1 | F14: 850 | G14: 5 | H14: 42.5 | I14: 807.5 | J14: {=_xlfn.XLOOKUP(C14,Customers!A:A,Customers!B:B)} -> Sara Khan
A15: 50014 | B15: 46055 | C15: 1012 | D15: P005 | E15: 3 | F15: 225 | G15: 15 | H15: 33.75 | I15: 191.25 | J15: {=_xlfn.XLOOKUP(C15,Customers!A:A,Customers!B:B)} -> Raj Kumar
A16: 50015 | B16: 46057 | C16: 1006 | D16: P002 | E16: 1 | F16: 320 | G16: 0 | H16: 0 | I16: 320 | J16: {=_xlfn.XLOOKUP(C16,Customers!A:A,Customers!B:B)} -> Neha Sharma
A17: 50016 | B17: 46059 | C17: 1002 | D17: P007 | E17: 2 | F17: 190 | G17: 0 | H17: 0 | I17: 190 | J17: {=_xlfn.XLOOKUP(C17,Customers!A:A,Customers!B:B)} -> Sara Khan
A18: 50017 | B18: 46062 | C18: 1001 | D18: P007 | E18: 2 | F18: 190 | G18: 5 | H18: 9.5 | I18: 180.5 | J18: {=_xlfn.XLOOKUP(C18,Customers!A:A,Customers!B:B)} -> Aman Singh
A19: 50018 | B19: 46064 | C19: 1012 | D19: P006 | E19: 4 | F19: 1120 | G19: 5 | H19: 56 | I19: 1064 | J19: {=_xlfn.XLOOKUP(C19,Customers!A:A,Customers!B:B)} -> Raj Kumar
A20: 50019 | B20: 46066 | C20: 1012 | D20: P007 | E20: 5 | F20: 475 | G20: 10 | H20: 47.5 | I20: 427.5 | J20: {=_xlfn.XLOOKUP(C20,Customers!A:A,Customers!B:B)} -> Raj Kumar
A21: 50020 | B21: 46068 | C21: 1017 | D21: P003 | E21: 1 | F21: 55 | G21: 0 | H21: 0 | I21: 55 | J21: {=_xlfn.XLOOKUP(C21,Customers!A:A,Customers!B:B)} -> David Smith
... A42: 50041 | B42: 46114 | C42: 1015 | D42: P005 | E42: 4 | F42: 300 | G42: 0 | H42: 0 | I42: 300 | J42: {=_xlfn.XLOOKUP(C42,Customers!A:A,Customers!B:B)} -> Luca Ferrari
A43: 50042 | B43: 46116 | C43: 1007 | D43: P007 | E43: 4 | F43: 380 | H43: 0 | I43: 380 | J43: {=_xlfn.XLOOKUP(C43,Customers!A:A,Customers!B:B)} -> Marco Bianchi
A44: 50043 | B44: 46119 | C44: 1012 | D44: P003 | E44: 3 | F44: 165 | G44: 15 | H44: 24.75 | I44: 140.25 | J44: {=_xlfn.XLOOKUP(C44,Customers!A:A,Customers!B:B)} -> Raj Kumar
A45: 50044 | B45: 46121 | C45: 1008 | D45: P005 | E45: 4 | F45: 300 | G45: 0 | H45: 0 | I45: 300 | J45: {=_xlfn.XLOOKUP(C45,Customers!A:A,Customers!B:B)} -> Priya Patel
A46: 50045 | B46: 46123 | C46: 1015 | D46: P004 | E46: 3 | F46: 75 | G46: 0 | H46: 0 | I46: 75 | J46: {=_xlfn.XLOOKUP(C46,Customers!A:A,Customers!B:B)} -> Luca Ferrari
A47: 50046 | B47: 46125 | C47: 1003 | D47: P005 | E47: 2 | F47: 150 | G47: 5 | H47: 7.5 | I47: 142.5 | J47: {=_xlfn.XLOOKUP(C47,Customers!A:A,Customers!B:B)} -> John Miller
A48: 50047 | B48: 46127 | C48: 1014 | D48: P008 | E48: 3 | F48: 1500 | G48: 0 | H48: 0 | I48: 1500 | J48: {=_xlfn.XLOOKUP(C48,Customers!A:A,Customers!B:B)} -> Gurpreet Singh
A49: 50048 | B49: 46130 | C49: 1017 | D49: P007 | E49: 3 | F49: 285 | G49: 0 | H49: 0 | I49: 285 | J49: {=_xlfn.XLOOKUP(C49,Customers!A:A,Customers!B:B)} -> David Smith
A50: 50049 | B50: 46132 | C50: 1004 | D50: P003 | E50: 4 | F50: 220 | G50: 0 | H50: 0 | I50: 220 | J50: {=_xlfn.XLOOKUP(C50,Customers!A:A,Customers!B:B)} -> Simran Kaur
A51: 50050 | B51: 46134 | C51: 1018 | D51: P003 | E51: 4 | F51: 220 | G51: 0 | H51: 0 | I51: 220 | J51: {=_xlfn.XLOOKUP(C51,Customers!A:A,Customers!B:B)} -> Manpreet Kaur
A52: 50051 | B52: 46136 | C52: 1008 | D52: P006 | E52: 1 | F52: 280 | G52: 10 | H52: 28 | I52: 252 | J52: {=_xlfn.XLOOKUP(C52,Customers!A:A,Customers!B:B)} -> Priya Patel
A53: 50052 | B53: 46138 | C53: 1004 | D53: P004 | E53: 1 | F53: 25 | G53: 0 | H53: 0 | I53: 25 | J53: {=_xlfn.XLOOKUP(C53,Customers!A:A,Customers!B:B)} -> Simran Kaur
A54: 50053 | B54: 46140 | C54: 1002 | D54: P002 | E54: 2 | F54: 640 | G54: 10 | H54: 64 | I54: 576 | J54: {=_xlfn.XLOOKUP(C54,Customers!A:A,Customers!B:B)} -> Sara Khan
A55: 50054 | B55: 46143 | C55: 1006 | D55: P002 | E55: 1 | F55: 320 | G55: 5 | H55: 16 | I55: 304 | J55: {=_xlfn.XLOOKUP(C55,Customers!A:A,Customers!B:B)} -> Neha Sharma
... A101: 50100 | B101: 46244 | C101: 1005 | D101: P008 | E101: 1 | F101: 500 | G101: 0 | H101: 0 | I101: 500 | J101: {=_xlfn.XLOOKUP(C101,Customers!A:A,Customers!B:B)} -> Daniel Rossi

Sheet Customers
A1: Customer_id | B1: customer_name | C1: city | D1: customer_segment
A2: 1001 | B2: Aman Singh | C2: Milan | D2: Consumer
A3: 1002 | B3: Sara Khan | C3: Rome | D3: Corporate
A4: 1003 | B4: John Miller | C4: Turin | D4: Consumer
A5: 1004 | B5: Simran Kaur | C5: Milan | D5: Consumer
A6: 1005 | B6: Daniel Rossi | C6: Bologna | D6: Corporate
A7: 1006 | B7: Neha Sharma | C7: Rome | D7: Consumer
A8: 1007 | B8: Marco Bianchi | C8: Milan | D8: Corporate
A9: 1008 | B9: Priya Patel | C9: Naples | D9: Consumer
A10: 1009 | B10: Alex Brown | C10: Turin | D10: Corporate
A11: 1010 | B11: Harpreet Kaur | C11: Milan | D11: Consumer
A12: 1011 | B12: Sofia Romano | C12: Rome | D12: Consumer
A13: 1012 | B13: Raj Kumar | C13: Bologna | D13: Corporate
... A21: 1020 | B21: Arjun Mehta | C21: Rome | D21: Consumer

Sheet Products
A1: product_id | B1: product_name | C1: category | D1: unit_price | E1: NET_SALES
A2: P001 | B2: Laptop | C2: Electronics | D2: 850 | E2: {=_xlfn.XLOOKUP(A2,Orders!D:D,Orders!I:I)} -> 3230
A3: P002 | B3: Monitor | C3: Electronics | D3: 320 | E3: {=_xlfn.XLOOKUP(A3,Orders!D:D,Orders!I:I)} -> 320
A4: P003 | B4: Keyboard | C4: Accessories | D4: 55 | E4: {=_xlfn.XLOOKUP(A4,Orders!D:D,Orders!I:I)} -> 52.25
A5: P004 | B5: Mouse | C5: Accessories | D5: 25 | E5: {=_xlfn.XLOOKUP(A5,Orders!D:D,Orders!I:I)} -> 100
A6: P005 | B6: Headset | C6: Accessories | D6: 75 | E6: {=_xlfn.XLOOKUP(A6,Orders!D:D,Orders!I:I)} -> 213.75
A7: P006 | B7: Printer | C7: Office | D7: 280 | E7: {=_xlfn.XLOOKUP(A7,Orders!D:D,Orders!I:I)} -> 252
A8: P007 | B8: Webcam | C8: Electronics | D8: 95 | E8: {=_xlfn.XLOOKUP(A8,Orders!D:D,Orders!I:I)} -> 95
A9: P008 | B9: Tablet | C9: Electronics | D9: 500 | E9: {=_xlfn.XLOOKUP(A9,Orders!D:D,Orders!I:I)} -> 500

Sheet Analysis_Practice
A1: order_id | B1: order_date | C1: customer_id | D1: product_id | E1: quantity | F1: sales | G1: discount_pct | H1: discount_amount | I1: net_sales | J1: customer_name | K1: city | L1: customer_segment | M1: product_name | N1: category | O1: unit_price | P1: month | Q1: sales_band
A2: 50001 | B2: 46027 | C2: 1007 | D2: P003 | E2: 1 | F2: 55 | G2: 5 | H2: 2.75 | I2: 52.25 | J2: Marco Bianchi | K2: Milan | L2: Corporate | M2: Keyboard | N2: Accessories | O2: 55 | P2: 2026-01 | Q2: Low
A3: 50002 | B3: 46029 | C3: 1020 | D3: P004 | E3: 4 | F3: 100 | G3: 0 | H3: 0 | I3: 100 | J3: Arjun Mehta | K3: Rome | L3: Consumer | M3: Mouse | N3: Accessories | O3: 25 | P3: 2026-01 | Q3: Low
A4: 50003 | B4: 46031 | C4: 1015 | D4: P008 | E4: 1 | F4: 500 | G4: 0 | H4: 0 | I4: 500 | J4: Luca Ferrari | K4: Turin | L4: Consumer | M4: Tablet | N4: Electronics | O4: 500 | P4: 2026-01 | Q4: Low
A5: 50004 | B5: 46033 | C5: 1011 | D5: P006 | E5: 1 | F5: 280 | G5: 10 | H5: 28 | I5: 252 | J5: Sofia Romano | K5: Rome | L5: Consumer | M5: Printer | N5: Office | O5: 280 | P5: 2026-01 | Q5: Low
A6: 50005 | B6: 46035 | C6: 1008 | D6: P003 | E6: 2 | F6: 110 | G6: 10 | H6: 11 | I6: 99 | J6: Priya Patel | K6: Naples | L6: Consumer | M6: Keyboard | N6: Accessories | O6: 55 | P6: 2026-01 | Q6: Low
A7: 50006 | B7: 46037 | C7: 1007 | D7: P003 | E7: 4 | F7: 220 | G7: 0 | H7: 0 | I7: 220 | J7: Marco Bianchi | K7: Milan | L7: Corporate | M7: Keyboard | N7: Accessories | O7: 55 | P7: 2026-01 | Q7: Low
A8: 50007 | B8: 46040 | C8: 1019 | D8: P001 | E8: 4 | F8: 3400 | G8: 5 | H8: 170 | I8: 3230 | J8: Giulia Conti | K8: Milan | L8: Corporate | M8: Laptop | N8: Electronics | O8: 850 | P8: 2026-01 | Q8: High
A9: 50008 | B9: 46042 | C9: 1011 | D9: P003 | E9: 2 | F9: 110 | H9: 0 | I9: 110 | J9: Sofia Romano | K9: Rome | L9: Consumer | M9: Keyboard | N9: Accessories | O9: 55 | P9: 2026-01 | Q9: Low
A10: 50009 | B10: 46044 | C10: 1011 | D10: P005 | E10: 3 | F10: 225 | G10: 5 | H10: 11.25 | I10: 213.75 | J10: Sofia Romano | K10: Rome | L10: Consumer | M10: Headset | N10: Accessories | O10: 75 | P10: 2026-01 | Q10: Low
A11: 50010 | B11: 46046 | C11: 1004 | D11: P007 | E11: 1 | F11: 95 | G11: 0 | H11: 0 | I11: 95 | J11: Simran Kaur | K11: Milan | L11: Consumer | M11: Webcam | N11: Electronics | O11: 95 | P11: 2026-01 | Q11: Low
A12: 50011 | B12: 46048 | C12: 1008 | D12: P006 | E12: 5 | F12: 1400 | G12: 5 | H12: 70 | I12: 1330 | J12: Priya Patel | K12: Naples | L12: Consumer | M12: Printer | N12: Office | O12: 280 | P12: 2026-01 | Q12: Medium
A13: 50012 | B13: 46051 | C13: 1003 | D13: P003 | E13: 1 | F13: 55 | G13: 15 | H13: 8.25 | I13: 46.75 | J13: John Miller | K13: Turin | L13: Consumer | M13: Keyboard | N13: Accessories | O13: 55 | P13: 2026-01 | Q13: Low
A14: 50013 | B14: 46053 | C14: 1002 | D14: P001 | E14: 1 | F14: 850 | G14: 5 | H14: 42.5 | I14: 807.5 | J14: Sara Khan | K14: Rome | L14: Corporate | M14: Laptop | N14: Electronics | O14: 850 | P14: 2026-01 | Q14: Medium
A15: 50014 | B15: 46055 | C15: 1012 | D15: P005 | E15: 3 | F15: 225 | G15: 15 | H15: 33.75 | I15: 191.25 | J15: Raj Kumar | K15: Bologna | L15: Corporate | M15: Headset | N15: Accessories | O15: 75 | P15: 2026-02 | Q15: Low
A16: 50015 | B16: 46057 | C16: 1006 | D16: P002 | E16: 1 | F16: 320 | G16: 0 | H16: 0 | I16: 320 | J16: Neha Sharma | K16: Rome | L16: Consumer | M16: Monitor | N16: Electronics | O16: 320 | P16: 2026-02 | Q16: Low
A17: 50016 | B17: 46059 | C17: 1002 | D17: P007 | E17: 2 | F17: 190 | G17: 0 | H17: 0 | I17: 190 | J17: Sara Khan | K17: Rome | L17: Corporate | M17: Webcam | N17: Electronics | O17: 95 | P17: 2026-02 | Q17: Low
A18: 50017 | B18: 46062 | C18: 1001 | D18: P007 | E18: 2 | F18: 190 | G18: 5 | H18: 9.5 | I18: 180.5 | J18: Aman Singh | K18: Milan | L18: Consumer | M18: Webcam | N18: Electronics | O18: 95 | P18: 2026-02 | Q18: Low
A19: 50018 | B19: 46064 | C19: 1012 | D19: P006 | E19: 4 | F19: 1120 | G19: 5 | H19: 56 | I19: 1064 | J19: Raj Kumar | K19: Bologna | L19: Corporate | M19: Printer | N19: Office | O19: 280 | P19: 2026-02 | Q19: Medium
A20: 50019 | B20: 46066 | C20: 1012 | D20: P007 | E20: 5 | F20: 475 | G20: 10 | H20: 47.5 | I20: 427.5 | J20: Raj Kumar | K20: Bologna | L20: Corporate | M20: Webcam | N20: Electronics | O20: 95 | P20: 2026-02 | Q20: Low
A21: 50020 | B21: 46068 | C21: 1017 | D21: P003 | E21: 1 | F21: 55 | G21: 0 | H21: 0 | I21: 55 | J21: David Smith | K21: Bologna | L21: Corporate | M21: Keyboard | N21: Accessories | O21: 55 | P21: 2026-02 | Q21: Low
... A42: 50041 | B42: 46114 | C42: 1015 | D42: P005 | E42: 4 | F42: 300 | G42: 0 | H42: 0 | I42: 300 | J42: Luca Ferrari | K42: Turin | L42: Consumer | M42: Headset | N42: Accessories | O42: 75 | P42: 2026-04 | Q42: Low
A43: 50042 | B43: 46116 | C43: 1007 | D43: P007 | E43: 4 | F43: 380 | H43: 0 | I43: 380 | J43: Marco Bianchi | K43: Milan | L43: Corporate | M43: Webcam | N43: Electronics | O43: 95 | P43: 2026-04 | Q43: Low
A44: 50043 | B44: 46119 | C44: 1012 | D44: P003 | E44: 3 | F44: 165 | G44: 15 | H44: 24.75 | I44: 140.25 | J44: Raj Kumar | K44: Bologna | L44: Corporate | M44: Keyboard | N44: Accessories | O44: 55 | P44: 2026-04 | Q44: Low
A45: 50044 | B45: 46121 | C45: 1008 | D45: P005 | E45: 4 | F45: 300 | G45: 0 | H45: 0 | I45: 300 | J45: Priya Patel | K45: Naples | L45: Consumer | M45: Headset | N45: Accessories | O45: 75 | P45: 2026-04 | Q45: Low
A46: 50045 | B46: 46123 | C46: 1015 | D46: P004 | E46: 3 | F46: 75 | G46: 0 | H46: 0 | I46: 75 | J46: Luca Ferrari | K46: Turin | L46: Consumer | M46: Mouse | N46: Accessories | O46: 25 | P46: 2026-04 | Q46: Low
A47: 50046 | B47: 46125 | C47: 1003 | D47: P005 | E47: 2 | F47: 150 | G47: 5 | H47: 7.5 | I47: 142.5 | J47: John Miller | K47: Turin | L47: Consumer | M47: Headset | N47: Accessories | O47: 75 | P47: 2026-04 | Q47: Low
A48: 50047 | B48: 46127 | C48: 1014 | D48: P008 | E48: 3 | F48: 1500 | G48: 0 | H48: 0 | I48: 1500 | J48: Gurpreet Singh | K48: Milan | L48: Corporate | M48: Tablet | N48: Electronics | O48: 500 | P48: 2026-04 | Q48: High
A49: 50048 | B49: 46130 | C49: 1017 | D49: P007 | E49: 3 | F49: 285 | G49: 0 | H49: 0 | I49: 285 | J49: David Smith | K49: Bologna | L49: Corporate | M49: Webcam | N49: Electronics | O49: 95 | P49: 2026-04 | Q49: Low
A50: 50049 | B50: 46132 | C50: 1004 | D50: P003 | E50: 4 | F50: 220 | G50: 0 | H50: 0 | I50: 220 | J50: Simran Kaur | K50: Milan | L50: Consumer | M50: Keyboard | N50: Accessories | O50: 55 | P50: 2026-04 | Q50: Low
A51: 50050 | B51: 46134 | C51: 1018 | D51: P003 | E51: 4 | F51: 220 | G51: 0 | H51: 0 | I51: 220 | J51: Manpreet Kaur | K51: Naples | L51: Consumer | M51: Keyboard | N51: Accessories | O51: 55 | P51: 2026-04 | Q51: Low
A52: 50051 | B52: 46136 | C52: 1008 | D52: P006 | E52: 1 | F52: 280 | G52: 10 | H52: 28 | I52: 252 | J52: Priya Patel | K52: Naples | L52: Consumer | M52: Printer | N52: Office | O52: 280 | P52: 2026-04 | Q52: Low
A53: 50052 | B53: 46138 | C53: 1004 | D53: P004 | E53: 1 | F53: 25 | G53: 0 | H53: 0 | I53: 25 | J53: Simran Kaur | K53: Milan | L53: Consumer | M53: Mouse | N53: Accessories | O53: 25 | P53: 2026-04 | Q53: Low
A54: 50053 | B54: 46140 | C54: 1002 | D54: P002 | E54: 2 | F54: 640 | G54: 10 | H54: 64 | I54: 576 | J54: Sara Khan | K54: Rome | L54: Corporate | M54: Monitor | N54: Electronics | O54: 320 | P54: 2026-04 | Q54: Low
A55: 50054 | B55: 46143 | C55: 1006 | D55: P002 | E55: 1 | F55: 320 | G55: 5 | H55: 16 | I55: 304 | J55: Neha Sharma | K55: Rome | L55: Consumer | M55: Monitor | N55: Electronics | O55: 320 | P55: 2026-05 | Q55: Low
... A101: 50100 | B101: 46244 | C101: 1005 | D101: P008 | E101: 1 | F101: 500 | G101: 0 | H101: 0 | I101: 500 | J101: Daniel Rossi | K101: Bologna | L101: Corporate | M101: Tablet | N101: Electronics | O101: 500 | P101: 2026-08 | Q101: Low

Sheet Sales Analysis
A1: "SALES ANALYSIS DASHBOARD-[DATE]"
A3: Total Orders | B3: Total Sales | C3: Net Sales | D3: Total Quantity | E3: Average Order Value
A4: =counta(Orders!A2:A1000) -> 100 | B4: =SUM(Orders!F2:F1000) -> 58400 | C4: =SUM(Orders!I2:I101) -> 56311.5 | D4: =SUM(Orders!E2:E1000) -> 268 | E4: =C4/A4 -> 563.115
A7: CITY WISE SALES | C7: CATEGORY WISE SALES
A8: City | B8: Total Sales | C8: Category | D8: Total Sales
A9: Milan | B9: =SUMIF(Analysis_Practice!K:K,"Milan",Analysis_Practice!F:F) -> 21405 | C9: Electronics | D9: =sumif(Analysis_Practice!N:N,C9,Analysis_Practice!F:F) -> 39775
A10: Rome | B10: =sumif(Analysis_Practice!K:K,"Rome",Analysis_Practice!F:F) -> 7715 | C10: Office | D10: =sumif(Analysis_Practice!N:N,C10,Analysis_Practice!F:F) -> 12880
A11: Turin | B11: =SUMIF(Analysis_Practice!K:K,"turin",Analysis_Practice!F:F) -> 11540 | C11: Accessories | D11: =sumif(Analysis_Practice!N:N,C11,Analysis_Practice!F:F) -> 5745
A12: Naples | B12: =SUMIF(Analysis_Practice!K:K,"naples",Analysis_Practice!F:F) -> 12085
A13: Bologna | B13: =SUMIF(Analysis_Practice!K:K,"bologna",Analysis_Practice!F:F) -> 5655
A15: Product Wise Sales | C15: MONTH | D15: TOTAL SALES
A16: Product Name | B16: Total Sales | C16: 46023 | D16: =SUMIF(Analysis_Practice!P:P,C16,Analysis_Practice!F:F) -> 7400
A17: Laptop | B17: =SUMIF(Analysis_Practice!M:M,"LAPTOP",Analysis_Practice!F:F) -> 23800 | C17: 46054 | D17: =SUMIF(Analysis_Practice!P:P,C17,Analysis_Practice!F:F) -> 6830
A18: Monitor | B18: =sumif(Analysis_Practice!M:M,"monitor",Analysis_Practice!F:F) -> 5440 | C18: 46082 | D18: =SUMIF(Analysis_Practice!P:P,C18,Analysis_Practice!F:F) -> 8030
A19: Keyboard | B19: =SUMIF(Analysis_Practice!M:M,"Keyboard",Analysis_Practice!F:F) -> 2145
A20: Printer | B20: =SUMIF(Analysis_Practice!M:M,"Printer",Analysis_Practice!F:F) -> 12880
A21: Webcam | B21: =SUMIF(Analysis_Practice!M:M,"Webcam",Analysis_Practice!F:F) -> 5035
A22: Tablet | B22: =SUMIF(Analysis_Practice!M:M,"Tablet",Analysis_Practice!F:F) -> 5500
A24: CUSTOMER WISE SALES
A25: Customer Name | B25: Total Sales
A26: Aman Singh | B26: =SUMIF(Analysis_Practice!J:J,A26,Analysis_Practice!F:F) -> 4080
A27: Sara Khan | B27: =SUMIF(Analysis_Practice!J:J,A27,Analysis_Practice!F:F) -> 3095
A28: Johan Miller | B28: =SUMIF(Analysis_Practice!J:J,A28,Analysis_Practice!F:F) -> 0
A29: Daniel Rossi | B29: =SUMIF(Analysis_Practice!J:J,A29,Analysis_Practice!F:F) -> 1635
A30: Neha Sharma | B30: =SUMIF(Analysis_Practice!J:J,A30,Analysis_Practice!F:F) -> 640 | D30: Customer_name | E30: SUM of net_sales
A31: Marco Bianchi | B31: =SUMIF(Analysis_Practice!J:J,A31,Analysis_Practice!F:F) -> 3990 | D31: Sofia Romano | E31: 800.75
A32: Priya Patel | B32: =SUMIF(Analysis_Practice!J:J,A32,Analysis_Practice!F:F) -> 3870 | D32: Simran Kaur | E32: 2031.25
A33: Alex Brown | B33: =SUMIF(Analysis_Practice!J:J,A33,Analysis_Practice!F:F) -> 6735 | D33: Sara Khan | E33: 2964.75
A34: Harpreet Kaur | B34: =SUMIF(Analysis_Practice!J:J,A34,Analysis_Practice!F:F) -> 2525 | D34: Raj Kumar | E34: 3241.75
A35: Sofia Romano | B35: =SUMIF(Analysis_Practice!J:J,A35,Analysis_Practice!F:F) -> 840 | D35: Priya Patel | E35: 3713
A36: Raj Kumar | B36: =SUMIF(Analysis_Practice!J:J,A36,Analysis_Practice!F:F) -> 3460 | D36: Neha Sharma | E36: 624
A37: Emma Wilson | B37: =SUMIF(Analysis_Practice!J:J,A37,Analysis_Practice!F:F) -> 5420 | D37: Marco Bianchi | E37: 3962.25
A38: Gurpreet Singh | B38: =SUMIF(Analysis_Practice!J:J,A38,Analysis_Practice!F:F) -> 2745 | D38: Manpreet Kaur | E38: 2742.25
A39: Luca Ferrari | B39: =SUMIF(Analysis_Practice!J:J,A39,Analysis_Practice!F:F) -> 3095 | D39: Luca Ferrari | E39: 3048
A40: Anita Verma | B40: =SUMIF(Analysis_Practice!J:J,A40,Analysis_Practice!F:F) -> 2455 | D40: John Miller | E40: 1677.75
A41: David Smith | B41: =SUMIF(Analysis_Practice!J:J,A41,Analysis_Practice!F:F) -> 560 | D41: Harpreet Kaur | E41: 2482.5
A42: Manpreet Kaur | B42: =SUMIF(Analysis_Practice!J:J,A42,Analysis_Practice!F:F) -> 2795 | D42: Gurpreet Singh | E42: 2633 | G42: order_date | H42: SUM of net_sales
A43: Giulia Conti | B43: =SUMIF(Analysis_Practice!J:J,A43,Analysis_Practice!F:F) -> 6030 | D43: Giulia Conti | E43: 5465.5 | H43: 0
A44: Arjun Mehta | B44: =SUMIF(Analysis_Practice!J:J,A44,Analysis_Practice!F:F) -> 685 | D44: Emma Wilson | E44: 5335 | G44: 46027 | H44: 52.25
D45: David Smith | E45: 549 | G45: 46029 | H45: 100
...
